<?xml version="1.0" ?>
<sdf version="1.8">
  <world name="nested_model_world">
    <model name="parent_model">
      <model name="nested_model">
        <pose>1 2 2  0 0 0</pose>
        <link name="nested_link1">
          <pose>3 1 1  0 0 1.5707</pose>
          <collision name="nested_collision1">
            <geometry>
              <sphere>
                <radius>2</radius>
              </sphere>
            </geometry>
          </collision>
        </link>
        <link name="nested_link2">
          <pose relative_to="nested_link1">0 1 0  1.5707 0 0</pose>
          <collision name="nested_collision2">
            <geometry>
              <sphere>
                <radius>2</radius>
              </sphere>
            </geometry>
          </collision>
        </link>
        <joint name="nested_joint" type="revolute">
          <parent>nested_link1</parent>
          <child>nested_link2</child>
          <axis>
            <xyz expressed_in="nested_link1">1 0 0</xyz>
          </axis>
        </joint>
      </model>
      <link name="link1">
        <collision name="collision">
          <geometry>
            <box>
              <size>1 2 3</size>
            </box>
          </geometry>
        </collision>
        <visual name="visual">
          <geometry>
            <box>
              <size>1 2 3</size>
            </box>
          </geometry>
        </visual>
      </link>

      <joint name="joint1" type="fixed">
         <parent>link1</parent>
         <child>nested_model::nested_link1</child>
      </joint>

      <!-- Use duplicate link names for testing that these don't collide
      with the links in the models above -->
      <model name="nested_model2">
        <link name="nested_link1"/>
      </model>
      <model name="nested_model3">
        <link name="link1"/>
      </model>
    </model>

    <model name="parent_model2">
      <model name="child_model">
        <model name="grand_child_model">
          <link name="link1"/>
        </model>
      </model>
    </model>
  </world>
</sdf>
